<?xml version="1.0" encoding="utf-8"?>
<!-- This URDF was automatically created by SolidWorks to URDF Exporter! Originally created by Stephen Brawner (brawner@gmail.com) 
     Commit Version: 1.6.0-1-g15f4949  Build Version: 1.6.7594.29634
     For more information, please see http://wiki.ros.org/sw_urdf_exporter -->
<robot
  name="sfinal">
  <link name="dummylink">
  </link>
  <joint name="dummyjoint" type="fixed">
    <parent link="dummylink" />
    <child link="body" />
  </joint>
  <link
    name="body">
    <inertial>
      <origin
        xyz="4.62807247742842E-18 0.0381 0.0421106215624483"
        rpy="0 0 0" />
      <mass
        value="31.7717428185929" />
      <inertia
        ixx="2.45443901786196"
        ixy="1.5021599923963E-18"
        ixz="-2.48737455154281E-16"
        iyy="3.02159355147635"
        iyz="7.22547203238704E-18"
        izz="0.598373472245415" />
    </inertial>
    <visual>
      <origin
        xyz="0 0 0"
        rpy="0 0 0" />
      <geometry>
        <mesh
          filename="package://sfinal/meshes/body.STL" />
      </geometry>
      <material
        name="">
        <color
          rgba="0.792156862745098 0.819607843137255 0.933333333333333 1" />
      </material>
    </visual>
    <collision>
      <origin
        xyz="0 0 0"
        rpy="0 0 0" />
      <geometry>
        <mesh
          filename="package://sfinal/meshes/body.STL" />
      </geometry>
    </collision>
  </link>
  <link
    name="Front_Peg_L">
    <inertial>
      <origin
        xyz="0.0414241862736242 0.0380999954119112 2.94223301278151E-09"
        rpy="0 0 0" />
      <mass
        value="0.0794178912632823" />
      <inertia
        ixx="1.93166442907651E-05"
        ixy="6.63314076682969E-12"
        ixz="-5.57898019363171E-13"
        iyy="0.000147464981510183"
        iyz="1.28012400109424E-10"
        izz="0.000161541723087934" />
    </inertial>
    <visual>
      <origin
        xyz="0 0 0"
        rpy="0 0 0" />
      <geometry>
        <mesh
          filename="package://sfinal/meshes/Front_Peg_L.STL" />
      </geometry>
      <material
        name="">
        <color
          rgba="0.792156862745098 0.819607843137255 0.933333333333333 1" />
      </material>
    </visual>
    <collision>
      <origin
        xyz="0 0 0"
        rpy="0 0 0" />
      <geometry>
        <mesh
          filename="package://sfinal/meshes/Front_Peg_L.STL" />
      </geometry>
    </collision>
  </link>
  <joint
    name="Peg_L_Joint"
    type="revolute">
    <origin
      xyz="-0.19241 0.24963 0"
      rpy="1.5708 0 -3.0857" />
    <parent
      link="body" />
    <child
      link="Front_Peg_L" />
    <axis
      xyz="0 1 0" />
    <limit
      lower="-1.047"
      upper="1.047"
      effort="0"
      velocity="0" />
  </joint>
  <!-- <transmission name="left_steering_transmission">
      <type>transmission_interface/SimpleTransmission</type>
      <joint name="Peg_L_Joint">
        <hardwareInterface>hardware_interface/EffortJointInterface</hardwareInterface>
      </joint>
      <actuator name="left_steering_transmission_motor">
        <mechanicalReduction>1</mechanicalReduction>
        <hardwareInterface>hardware_interface/EffortJointInterface</hardwareInterface>
      </actuator>
  </transmission> -->
  <link
    name="Front_Wheel_L">
    <inertial>
      <origin
        xyz="-0.0378620487147911 5.55111512312578E-17 0"
        rpy="0 0 0" />
      <mass
        value="2.43249992415545" />
      <inertia
        ixx="0.0127509821649285"
        ixy="6.7762635780344E-19"
        ixz="2.74438674910393E-19"
        iyy="0.00755250482076537"
        iyz="-2.16840434497101E-19"
        izz="0.00755250482076537" />
    </inertial>
    <visual>
      <origin
        xyz="0 0 0"
        rpy="0 0 0" />
      <geometry>
        <mesh
          filename="package://sfinal/meshes/Front_Wheel_L.STL" />
      </geometry>
      <material
        name="">
        <color
          rgba="0.792156862745098 0.819607843137255 0.933333333333333 1" />
      </material>
    </visual>
    <collision>
      <origin
        xyz="0 0 0"
        rpy="0 0 0" />
      <geometry>
        <mesh
          filename="package://sfinal/meshes/Front_Wheel_L.STL" />
      </geometry>
    </collision>
  </link>
  <joint
    name="Wheel_L_Joint"
    type="continuous">
    <origin
      xyz="0.051038 0.0381 0"
      rpy="-1.7102 0 3.1416" />
    <parent
      link="Front_Peg_L" />
    <child
      link="Front_Wheel_L" />
    <axis
      xyz="1 0 0" />
  </joint>
  <link
    name="Front_Peg_R">
    <inertial>
      <origin
        xyz="0.0414241862180602 -0.0381000063821036 4.02376604258237E-09"
        rpy="0 0 0" />
      <mass
        value="0.0794178917151869" />
      <inertia
        ixx="1.9316644225953E-05"
        ixy="9.24219008763816E-12"
        ixz="-1.65264621611017E-12"
        iyy="0.000147464980958411"
        iyz="1.27986923700734E-10"
        izz="0.000161541722659423" />
    </inertial>
    <visual>
      <origin
        xyz="0 0 0"
        rpy="0 0 0" />
      <geometry>
        <mesh
          filename="package://sfinal/meshes/Front_Peg_R.STL" />
      </geometry>
      <material
        name="">
        <color
          rgba="0.792156862745098 0.819607843137255 0.933333333333333 1" />
      </material>
    </visual>
    <collision>
      <origin
        xyz="0 0 0"
        rpy="0 0 0" />
      <geometry>
        <mesh
          filename="package://sfinal/meshes/Front_Peg_R.STL" />
      </geometry>
    </collision>
  </link>
  <joint
    name="Peg_R_Joint"
    type="revolute">
    <origin
      xyz="0.19241 0.24963 0"
      rpy="-1.5708 0 -0.08116" />
    <parent
      link="body" />
    <child
      link="Front_Peg_R" />
    <axis
      xyz="0 1 0" />
    <limit
      lower="-1.047"
      upper="1.047"
      effort="0"
      velocity="0" />
  </joint>
    <!-- <transmission name="right_steering_transmission">
      <type>transmission_interface/SimpleTransmission</type>
      <joint name="Peg_R_Joint">
        <hardwareInterface>hardware_interface/EffortJointInterface</hardwareInterface>
      </joint>
      <actuator name="left_steering_transmission_motor">
        <mechanicalReduction>1</mechanicalReduction>
        <hardwareInterface>hardware_interface/EffortJointInterface</hardwareInterface>
      </actuator>
  </transmission> -->
  <link
    name="Front_Wheel_R">
    <inertial>
      <origin
        xyz="0.0572001403278296 -4.16333634234434E-16 1.66533453693773E-16"
        rpy="0 0 0" />
      <mass
        value="2.43249992415545" />
      <inertia
        ixx="0.0127509821649286"
        ixy="7.15573433840433E-18"
        ixz="-2.22261445359528E-18"
        iyy="0.00755250482076537"
        iyz="-3.25260651745651E-19"
        izz="0.00755250482076537" />
    </inertial>
    <visual>
      <origin
        xyz="0 0 0"
        rpy="0 0 0" />
      <geometry>
        <mesh
          filename="package://sfinal/meshes/Front_Wheel_R.STL" />
      </geometry>
      <material
        name="">
        <color
          rgba="0.792156862745098 0.819607843137255 0.933333333333333 1" />
      </material>
    </visual>
    <collision>
      <origin
        xyz="0 0 0"
        rpy="0 0 0" />
      <geometry>
        <mesh
          filename="package://sfinal/meshes/Front_Wheel_R.STL" />
      </geometry>
    </collision>
  </link>
  <joint
    name="Wheel_R_Joint"
    type="continuous">
    <origin
      xyz="0.0317 -0.0381 0"
      rpy="2.9611 0 0" />
    <parent
      link="Front_Peg_R" />
    <child
      link="Front_Wheel_R" />
    <axis
      xyz="1 0 0" />
  </joint>
  <link
    name="Back_Wheel_L">
    <inertial>
      <origin
        xyz="4.85722573273506E-16 0.163001147666413 2.58126853225349E-15"
        rpy="0 0 0" />
      <mass
        value="2.52323603243744" />
      <inertia
        ixx="0.00817145539435747"
        ixy="1.47706606444059E-18"
        ixz="-2.16840434497101E-19"
        iyy="0.0127575008904871"
        iyz="3.48736938642137E-17"
        izz="0.00817145539435747" />
    </inertial>
    <visual>
      <origin
        xyz="0 0 0"
        rpy="0 0 0" />
      <geometry>
        <mesh
          filename="package://sfinal/meshes/Back_Wheel_L.STL" />
      </geometry>
      <material
        name="">
        <color
          rgba="0.792156862745098 0.819607843137255 0.933333333333333 1" />
      </material>
    </visual>
    <collision>
      <origin
        xyz="0 0 0"
        rpy="0 0 0" />
      <geometry>
        <mesh
          filename="package://sfinal/meshes/Back_Wheel_L.STL" />
      </geometry>
    </collision>
  </link>
  <joint
    name="Back_Wheel_L_Joint"
    type="continuous">
    <origin
      xyz="-0.1397 -0.254 0.0381"
      rpy="0 -1.113 1.5708" />
    <parent
      link="body" />
    <child
      link="Back_Wheel_L" />
    <axis
      xyz="0 1 0" />
  </joint>
    <!-- <transmission name="Back_Wheel_L_Transmission">
      <type>transmission_interface/SimpleTransmission</type>
      <joint name="Back_Wheel_L_Joint">
        <hardwareInterface>hardware_interface/EffortJointInterface</hardwareInterface>
      </joint>
      <actuator name="left_steering_transmission_motor">
        <mechanicalReduction>1</mechanicalReduction>
        <hardwareInterface>hardware_interface/EffortJointInterface</hardwareInterface>
      </actuator>
  </transmission> -->
  <link
    name="Back_Wheel_R">
    <inertial>
      <origin
        xyz="-6.38378239159465E-16 0.163001147666413 -5.63438184997267E-15"
        rpy="0 0 0" />
      <mass
        value="2.52323603243744" />
      <inertia
        ixx="0.00817145539435747"
        ixy="2.70573768306384E-19"
        ixz="-4.33680868994202E-19"
        iyy="0.0127575008904871"
        iyz="-1.25839697405665E-16"
        izz="0.00817145539435747" />
    </inertial>
    <visual>
      <origin
        xyz="0 0 0"
        rpy="0 0 0" />
      <geometry>
        <mesh
          filename="package://sfinal/meshes/Back_Wheel_R.STL" />
      </geometry>
      <material
        name="">
        <color
          rgba="0.792156862745098 0.819607843137255 0.933333333333333 1" />
      </material>
    </visual>
    <collision>
      <origin
        xyz="0 0 0"
        rpy="0 0 0" />
      <geometry>
        <mesh
          filename="package://sfinal/meshes/Back_Wheel_R.STL" />
      </geometry>
    </collision>
  </link>
  <joint
    name="Back_Wheel_R_Joint"
    type="continuous">
    <origin
      xyz="0.1397 -0.254 0.0381"
      rpy="0 0.25328 -1.5708" />
    <parent
      link="body" />
    <child
      link="Back_Wheel_R" />
    <axis
      xyz="0 1 0" />
  </joint>
  <!-- <transmission name="Back_Wheel_R_Transmission">
      <type>transmission_interface/SimpleTransmission</type>
      <joint name="Back_Wheel_R_Joint">
        <hardwareInterface>hardware_interface/EffortJointInterface</hardwareInterface>
      </joint>
      <actuator name="left_steering_transmission_motor">
        <mechanicalReduction>1</mechanicalReduction>
        <hardwareInterface>hardware_interface/EffortJointInterface</hardwareInterface>
      </actuator>
  </transmission> -->

<transmission name="left_steering_transmission">
    <type>transmission_interface/SimpleTransmission</type>
    <joint name="Peg_L_Joint">
      <hardwareInterface>hardware_interface/EffortJointInterface</hardwareInterface>
    </joint>
    <actuator name="left_steering_transmission_motor"/>
  </transmission>
  <transmission name="right_steering_transmission">
    <type>transmission_interface/SimpleTransmission</type>
    <joint name="Peg_R_Joint">
      <hardwareInterface>hardware_interface/EffortJointInterface</hardwareInterface>
    </joint>
    <actuator name="right_steering_transmission_motor"/>
  </transmission>
  <transmission name="back_left_wheel_transmission">
    <type>transmission_interface/SimpleTransmission</type>
    <joint name="Back_Wheel_L_Joint">
      <hardwareInterface>hardware_interface/EffortJointInterface</hardwareInterface>
    </joint>
    <actuator name="back_left_wheel_transmission_motor"/>
  </transmission>
  <transmission name="back_right_wheel_transmission">
    <type>transmission_interface/SimpleTransmission</type>
    <joint name="Back_Wheel_R_Joint">
      <hardwareInterface>hardware_interface/EffortJointInterface</hardwareInterface>
    </joint>
    <actuator name="back_right_wheel_transmission_motor"/>
  </transmission>

</robot>